Workbook

Sheet README
A1: salaryfree — Calculator Verification Workbook
A3: PURPOSE
A4: This workbook replicates the app's Quick and Standard tier financial calculations using
A5: Excel formulae. Enter inputs (yellow cells) and compare outputs to the app.
A7: SHEETS
A8: Rates — Shared return / inflation constants (edit here to test scenarios)
A9: FOUNDER_Quick — Quick tier: runway & target number (Founder scenario)
A10: RETIRE_Quick — Quick tier: corpus gap & monthly savings (Retirement scenario)
A11: FOUNDER_Std — Standard tier: 20-year projection (Founder scenario)
A12: RETIRE_Std — Standard tier: 20-year projection (Retirement scenario)
A14: COLOUR CODE
A15: Yellow → Input fields (edit these)
... A35: • sustainable = final_corpus > annual_survival × 5

Sheet Rates
A1: Rate / Constant Inputs (green = default from app)
A2: Parameter | B2: Value (edit) | C2: Notes
A3: Liquid Return | B3: 0.05 | C3: FD / savings accounts, liquid MFs
A4: Semi-liquid Return | B4: 0.08 | C4: Short-term debt MFs, bonds
A5: Growth Return | B5: 0.1 | C5: Equity MFs, stocks
A6: Property Appreciation | B6: 0.04 | C6: Real estate capital appreciation
A7: Property Rental Yield | B7: 0.02 | C7: Gross rental / property value
A8: Needs Inflation | B8: 0.06 | C8: Essential expenses inflation
A9: Wants Inflation | B9: 0.07 | C9: Lifestyle expenses inflation
A10: Passive Income Growth | B10: 0.04 | C10: Dividend / rental income growth
A11: SWR Rate | B11: 0.04 | C11: Safe Withdrawal Rate (4% rule)
A12: Pension Inflation | B12: 0.04 | C12: Pension increase per year
A13: Needs % of Expenses | B13: 0.6 | C13: Default 60% of monthly expenses
A14: Wants % of Expenses | B14: 0.4 | C14: Default 40% of monthly expenses

Sheet FOUNDER_Quick
A1: FOUNDER — Quick Tier Inputs
A2: Input | B2: Value (₹ or months) | C2: Notes
A3: Monthly Expenses (total) | B3: 250000 | C3: Total household monthly spend
A4: Needs % of Expenses | B4: =Rates!$B$13 -> 0.6 | C4: From Rates sheet
A5: Wants % of Expenses | B5: =Rates!$B$14 -> 0.4 | C5: From Rates sheet
A6: Living Assets (liquid+semi) | B6: 2000000 | C6: Liquid + semi-liquid assets
A7: Security Assets (growth+property) | B7: 10000000 | C7: Growth + property assets
A8: Monthly Passive Income | B8: 0 | C8: Rent, dividends, etc.
A9: Emergency Fund Months | B9: 6 | C9: Months of needs to lock away
A10: Bootstrap Capital | B10: 0 | C10: Capital committed to venture
A11: One-time Expenses | B11: 0 | C11: Moving costs, equipment, etc.
A13: Computed Outputs (match against app)
A14: Output | B14: Value | C14: Formula / Logic
A15: Monthly Survival (Needs) | B15: =B3*B4 -> 150000 | C15: monthly_expenses × needs%
A16: Monthly Lifestyle (Wants) | B16: =B3*B5 -> 100000 | C16: monthly_expenses × wants%
A17: Total Assets | B17: =B6+B7 -> 12000000 | C17: living_assets + security_assets
A18: Emergency Fund Lock | B18: =B15*B9 -> 900000 | C18: monthly_survival × emergency_months
A19: Available Cash | B19: =MAX(0,B17-B18-B10-B11) -> 11100000 | C19: total_assets − lock − bootstrap − one_time
A20: Net Austerity Burn/mo | B20: =MAX(0,B15-B8) -> 150000 | C20: monthly_survival − monthly_passive
A21: Net Comfort Burn/mo | B21: =MAX(0,B3-B8) -> 250000 | C21: monthly_expenses − monthly_passive
A22: Austerity Runway (months) | B22: =IF(B20>0,B19/B20,"∞") -> 74 | C22: available_cash ÷ net_austerity_burn
A23: Comfort Runway (months) | B23: =IF(B21>0,B19/B21,"∞") -> 44.4 | C23: available_cash ÷ net_comfort_burn
A24: Austerity Runway (years) | B24: =IF(ISNUMBER(B22),B22/12,"∞") -> 6.1666667 | C24: months ÷ 12
A25: Comfort Runway (years) | B25: =IF(ISNUMBER(B23),B23/12,"∞") -> 3.7 | C25: months ÷ 12
A26: Target Number (25× rule) | B26: =B15*12*25 -> 45000000 | C26: monthly_survival × 12 × 25 (4% SWR corpus)
A27: Target Gap | B27: =MAX(0,B26-B17) -> 33000000 | C27: max(0, target − total_assets)
A29: How to use
A30: 1. Fill yellow cells with your inputs. 2. Compare 'Computed Outputs' to the app's Quick-tier results screen. 3. Discrepancies > ₹1 indicate a bug in either the app or this sheet.

Sheet RETIRE_Quick
A1: RETIREMENT — Quick Tier Inputs
A2: Input | B2: Value | C2: Notes
A3: Current Age | B3: 50 | C3: years
A4: Retirement Age | B4: 60 | C4: years
A5: Life Expectancy | B5: 85 | C5: years
A6: Monthly Expenses (total) | B6: 80000 | C6: ₹/month
A7: Needs % of Expenses | B7: =Rates!$B$13 -> 0.6 | C7: From Rates sheet
A8: Wants % of Expenses | B8: =Rates!$B$14 -> 0.4 | C8: From Rates sheet
A9: Living Assets | B9: 3000000 | C9: ₹
A10: Security Assets | B10: 1000000 | C10: ₹
A11: Monthly Passive Income | B11: 0 | C11: ₹/month
A12: Emergency Fund Months | B12: 6 | C12: months
A13: One-time Expenses | B13: 0 | C13: ₹
A15: Computed Outputs
A16: Output | B16: Value | C16: Formula / Logic
A17: Years to Retirement | B17: =MAX(0,B4-B3) -> 10 | C17: retirement_age − current_age
A18: Retirement Duration (yrs) | B18: =MAX(0,B5-B4) -> 25 | C18: life_expectancy − retirement_age
A19: Monthly Survival (Needs) | B19: =B6*B7 -> 48000 | C19: monthly_expenses × needs%
A20: Monthly Lifestyle (Wants) | B20: =B6*B8 -> 32000 | C20: monthly_expenses × wants%
A21: Total Assets | B21: =B9+B10 -> 4000000 | C21: living + security
A22: Emergency Fund Lock | B22: =B19*B12 -> 288000 | C22: monthly_survival × emergency_months
A23: Available Cash | B23: =MAX(0,B21-B22-B13) -> 3712000 | C23: total_assets − lock − one_time
A24: Required Corpus (25× rule) | B24: =B6*12*25 -> 24000000 | C24: monthly_expenses × 12 × 25
A25: Current Corpus | B25: =B21 -> 4000000 | C25: total_assets
A26: Corpus Gap | B26: =MAX(0,B24-B25) -> 20000000 | C26: max(0, required − current)
A27: Months to Retirement | B27: =B17*12 -> 120 | C27: years × 12
A28: Monthly Savings Needed | B28: =IF(B27>0,B26/B27,0) -> 166666.67 | C28: Simple: gap ÷ months_remaining
A29: Net Austerity Burn/mo | B29: =MAX(0,B19-B11) -> 48000 | C29: monthly_survival − monthly_passive
A30: Net Comfort Burn/mo | B30: =MAX(0,B6-B11) -> 80000 | C30: monthly_expenses − monthly_passive
A31: Austerity Runway (months) | B31: =IF(B29>0,B23/B29,"∞") -> 77.333333 | C31: available_cash ÷ net_austerity_burn
A32: Comfort Runway (months) | B32: =IF(B30>0,B23/B30,"∞") -> 46.4 | C32: available_cash ÷ net_comfort_burn
A33: Annual Passive Income | B33: =B11*12 -> 0 | C33: monthly_passive × 12
A34: Annual Expenses | B34: =B6*12 -> 960000 | C34: monthly_expenses × 12
A35: Passive Coverage % | B35: =IF(B34>0,B33/B34,"N/A") -> 0 | C35: passive_income ÷ annual_expenses
A36: Can Retire Now? | B36: =IF(OR(B25>=B24,B33>=B34),"YES — corpus or passive sufficient","NO — gap remains") -> NO — gap remains | C36: current_corpus >= required OR passive >= annual_expenses

Sheet FOUNDER_Std
A1: FOUNDER — Standard Tier: 20-Year Projection
A2: Input | B2: Value | C2: Notes
A3: Monthly Expenses (total) | B3: 100000 | C3: ₹/month
A4: Liquid Savings | B4: 1500000 | C4: FD, savings accounts, liquid MFs
A5: Semi-liquid Savings | B5: 2000000 | C5: Short-term debt MFs, bonds
A6: Growth Assets | B6: 10000000 | C6: Equity MFs, direct stocks
A7: Property Value | B7: 25000000 | C7: Residential / commercial property
A8: Monthly Passive Income | B8: 0 | C8: Dividends, rent, royalties
A9: Emergency Fund Months | B9: 6 | C9: months of needs locked
A10: Bootstrap Capital | B10: 0 | C10: Capital committed to venture upfront
A11: One-time Expenses | B11: 0 | C11: Upfront setup costs
A12: Founder Salary (monthly) | B12: 0 | C12: Salary drawn from venture once live
A13: Salary Start Month | B13: 0 | C13: Month offset (0=immediately, 12=after 1yr)
A15: Derived Inputs (from Rates sheet)
A16: Needs % / Wants % | B16: =Rates!$B$13&" / "&Rates!$B$14 -> 0.6 / 0.4 | C16: 60% / 40% of monthly expenses (edit in Rates)
A17: Monthly Survival (Needs) | B17: =B3*Rates!$B$13 -> 60000 | C17: =monthly_expenses * needs% -> #NAME?
A18: Emergency Lock | B18: =B17*B9 -> 360000 | C18: =monthly_survival * emergency_months -> #NAME?
A19: Proj. Liquid (start) | B19: =MAX(0,B4-MIN(B4,B18+B10+B11)) -> 1140000 | C19: liquid − min(liquid, lock+bootstrap+one_time)
A20: Proj. Semi (start) | B20: =MAX(0,B5-MIN(B5,MAX(0,B18+B10+B11-B4))) -> 2000000 | C20: semi − overflow of deductions after liquid exhausted
A21: Total Assets | B21: =B4+B5+B6+B7 -> 38500000
A22: Available Cash | B22: =MAX(0,B21-B18-B10-B11) -> 38140000
A23: Austerity Runway (months) | B23: =IF(MAX(0,B17-B8)>0,B22/MAX(0,B17-B8),"∞") -> 635.66667
A24: Target Number (25×) | B24: =B17*12*25 -> 18000000
A25: Target Gap | B25: =MAX(0,B24-B21) -> 0
A26: Salary Start Year | B26: =INT(B13/12) -> 0 | C26: salary_start_month ÷ 12 (truncated)
A28: Year | B28: Liquid (start) | C28: Semi (start) | D28: Growth (start) | E28: Property (start) | F28: Total Assets | G28: Annual Needs | H28: Annual Wants | I28: One-time | J28: Total Expenses | K28: Passive Income | L28: Rental Income | M28: Scenario Income | N28: Total Income | O28: Net Cashflow | P28: Deficit | Q28: Draw Liquid | R28: Draw Semi | S28: Draw Growth | T28: Surplus→Growth | U28: Free-up? | V28: Depleted?
A29: 0 | B29: =B19 -> 1140000 | C29: =B20 -> 2000000 | D29: =$B$6 -> 10000000 | E29: =$B$7 -> 25000000 | F29: =B29+C29+D29+E29 -> 38140000 | G29: =B17*12 -> 720000 | H29: =B3*Rates!$B$14*12 -> 480000 | I29: 0 | J29: =G29+H29+I29 -> 1200000 | K29: =$B$8*12 -> 0 | L29: =E29*Rates!$B$7 -> 500000 | M29: =IF(A29>=$B$26,$B$12*12,0) -> 0 | N29: =K29+L29+M29 -> 500000 | O29: =N29-J29 -> -700000 | P29: =MAX(0,-O29) -> 700000 | Q29: =MIN(B29,P29) -> 700000 | R29: =MIN(C29,MAX(0,P29-Q29)) -> 0 | S29: =MAX(0,P29-Q29-R29) -> 0 | T29: =MAX(0,O29) -> 0 | U29: =IF(N29>=J29,"✓","") | V29: =IF(F29<=0,"✗","")
A30: 1 | B30: =(B29-Q29)*( 1+Rates!$B$3) -> 462000 | C30: =(C29-R29)*(1+Rates!$B$4) -> 2160000 | D30: =(D29-S29+T29)*(1+Rates!$B$5) -> 11000000 | E30: =E29*(1+Rates!$B$6) -> 26000000 | F30: =B30+C30+D30+E30 -> 39622000 | G30: =G29*(1+Rates!$B$8) -> 763200 | H30: =H29*(1+Rates!$B$9) -> 513600 | I30: 0 | J30: =G30+H30+I30 -> 1276800 | K30: =K29*(1+Rates!$B$10) -> 0 | L30: =E30*Rates!$B$7 -> 520000 | M30: =IF(A30>=$B$26,IF(M29=0,$B$12*12,M29*(1+Rates!$B$10)),0) -> 0 | N30: =K30+L30+M30 -> 520000 | O30: =N30-J30 -> -756800 | P30: =MAX(0,-O30) -> 756800 | Q30: =MIN(B30,P30) -> 462000 | R30: =MIN(C30,MAX(0,P30-Q30)) -> 294800 | S30: =MAX(0,P30-Q30-R30) -> 0 | T30: =MAX(0,O30) -> 0 | U30: =IF(N30>=J30,"✓","") | V30: =IF(F30<=0,"✗","")
A31: 2 | B31: =(B30-Q30)*( 1+Rates!$B$3) -> 0 | C31: =(C30-R30)*(1+Rates!$B$4) -> 2014416 | D31: =(D30-S30+T30)*(1+Rates!$B$5) -> 12100000 | E31: =E30*(1+Rates!$B$6) -> 27040000 | F31: =B31+C31+D31+E31 -> 41154416 | G31: =G30*(1+Rates!$B$8) -> 808992 | H31: =H30*(1+Rates!$B$9) -> 549552 | I31: 0 | J31: =G31+H31+I31 -> 1358544 | K31: =K30*(1+Rates!$B$10) -> 0 | L31: =E31*Rates!$B$7 -> 540800 | M31: =IF(A31>=$B$26,IF(M30=0,$B$12*12,M30*(1+Rates!$B$10)),0) -> 0 | N31: =K31+L31+M31 -> 540800 | O31: =N31-J31 -> -817744 | P31: =MAX(0,-O31) -> 817744 | Q31: =MIN(B31,P31) -> 0 | R31: =MIN(C31,MAX(0,P31-Q31)) -> 817744 | S31: =MAX(0,P31-Q31-R31) -> 0 | T31: =MAX(0,O31) -> 0 | U31: =IF(N31>=J31,"✓","") | V31: =IF(F31<=0,"✗","")
A32: 3 | B32: =(B31-Q31)*( 1+Rates!$B$3) -> 0 | C32: =(C31-R31)*(1+Rates!$B$4) -> 1292405.8 | D32: =(D31-S31+T31)*(1+Rates!$B$5) -> 13310000 | E32: =E31*(1+Rates!$B$6) -> 28121600 | F32: =B32+C32+D32+E32 -> 42724006 | G32: =G31*(1+Rates!$B$8) -> 857531.52 | H32: =H31*(1+Rates!$B$9) -> 588020.64 | I32: 0 | J32: =G32+H32+I32 -> 1445552.2 | K32: =K31*(1+Rates!$B$10) -> 0 | L32: =E32*Rates!$B$7 -> 562432 | M32: =IF(A32>=$B$26,IF(M31=0,$B$12*12,M31*(1+Rates!$B$10)),0) -> 0 | N32: =K32+L32+M32 -> 562432 | O32: =N32-J32 -> -883120.16 | P32: =MAX(0,-O32) -> 883120.16 | Q32: =MIN(B32,P32) -> 0 | R32: =MIN(C32,MAX(0,P32-Q32)) -> 883120.16 | S32: =MAX(0,P32-Q32-R32) -> 0 | T32: =MAX(0,O32) -> 0 | U32: =IF(N32>=J32,"✓","") | V32: =IF(F32<=0,"✗","")
A33: 4 | B33: =(B32-Q32)*( 1+Rates!$B$3) -> 0 | C33: =(C32-R32)*(1+Rates!$B$4) -> 442028.45 | D33: =(D32-S32+T32)*(1+Rates!$B$5) -> 14641000 | E33: =E32*(1+Rates!$B$6) -> 29246464 | F33: =B33+C33+D33+E33 -> 44329492 | G33: =G32*(1+Rates!$B$8) -> 908983.41 | H33: =H32*(1+Rates!$B$9) -> 629182.08 | I33: 0 | J33: =G33+H33+I33 -> 1538165.5 | K33: =K32*(1+Rates!$B$10) -> 0 | L33: =E33*Rates!$B$7 -> 584929.28 | M33: =IF(A33>=$B$26,IF(M32=0,$B$12*12,M32*(1+Rates!$B$10)),0) -> 0 | N33: =K33+L33+M33 -> 584929.28 | O33: =N33-J33 -> -953236.22 | P33: =MAX(0,-O33) -> 953236.22 | Q33: =MIN(B33,P33) -> 0 | R33: =MIN(C33,MAX(0,P33-Q33)) -> 442028.45 | S33: =MAX(0,P33-Q33-R33) -> 511207.77 | T33: =MAX(0,O33) -> 0 | U33: =IF(N33>=J33,"✓","") | V33: =IF(F33<=0,"✗","")
A34: 5 | B34: =(B33-Q33)*( 1+Rates!$B$3) -> 0 | C34: =(C33-R33)*(1+Rates!$B$4) -> 0 | D34: =(D33-S33+T33)*(1+Rates!$B$5) -> 15542771 | E34: =E33*(1+Rates!$B$6) -> 30416323 | F34: =B34+C34+D34+E34 -> 45959094 | G34: =G33*(1+Rates!$B$8) -> 963522.42 | H34: =H33*(1+Rates!$B$9) -> 673224.83 | I34: 0 | J34: =G34+H34+I34 -> 1636747.2 | K34: =K33*(1+Rates!$B$10) -> 0 | L34: =E34*Rates!$B$7 -> 608326.45 | M34: =IF(A34>=$B$26,IF(M33=0,$B$12*12,M33*(1+Rates!$B$10)),0) -> 0 | N34: =K34+L34+M34 -> 608326.45 | O34: =N34-J34 -> -1028420.8 | P34: =MAX(0,-O34) -> 1028420.8 | Q34: =MIN(B34,P34) -> 0 | R34: =MIN(C34,MAX(0,P34-Q34)) -> 0 | S34: =MAX(0,P34-Q34-R34) -> 1028420.8 | T34: =MAX(0,O34) -> 0 | U34: =IF(N34>=J34,"✓","") | V34: =IF(F34<=0,"✗","")
A35: 6 | B35: =(B34-Q34)*( 1+Rates!$B$3) -> 0 | C35: =(C34-R34)*(1+Rates!$B$4) -> 0 | D35: =(D34-S34+T34)*(1+Rates!$B$5) -> 15965786 | E35: =E34*(1+Rates!$B$6) -> 31632975 | F35: =B35+C35+D35+E35 -> 47598761 | G35: =G34*(1+Rates!$B$8) -> 1021333.8 | H35: =H34*(1+Rates!$B$9) -> 720350.57 | I35: 0 | J35: =G35+H35+I35 -> 1741684.3 | K35: =K34*(1+Rates!$B$10) -> 0 | L35: =E35*Rates!$B$7 -> 632659.51 | M35: =IF(A35>=$B$26,IF(M34=0,$B$12*12,M34*(1+Rates!$B$10)),0) -> 0 | N35: =K35+L35+M35 -> 632659.51 | O35: =N35-J35 -> -1109024.8 | P35: =MAX(0,-O35) -> 1109024.8 | Q35: =MIN(B35,P35) -> 0 | R35: =MIN(C35,MAX(0,P35-Q35)) -> 0 | S35: =MAX(0,P35-Q35-R35) -> 1109024.8 | T35: =MAX(0,O35) -> 0 | U35: =IF(N35>=J35,"✓","") | V35: =IF(F35<=0,"✗","")
A36: 7 | B36: =(B35-Q35)*( 1+Rates!$B$3) -> 0 | C36: =(C35-R35)*(1+Rates!$B$4) -> 0 | D36: =(D35-S35+T35)*(1+Rates!$B$5) -> 16342437 | E36: =E35*(1+Rates!$B$6) -> 32898294 | F36: =B36+C36+D36+E36 -> 49240731 | G36: =G35*(1+Rates!$B$8) -> 1082613.8 | H36: =H35*(1+Rates!$B$9) -> 770775.11 | I36: 0 | J36: =G36+H36+I36 -> 1853388.9 | K36: =K35*(1+Rates!$B$10) -> 0 | L36: =E36*Rates!$B$7 -> 657965.89 | M36: =IF(A36>=$B$26,IF(M35=0,$B$12*12,M35*(1+Rates!$B$10)),0) -> 0 | N36: =K36+L36+M36 -> 657965.89 | O36: =N36-J36 -> -1195423 | P36: =MAX(0,-O36) -> 1195423 | Q36: =MIN(B36,P36) -> 0 | R36: =MIN(C36,MAX(0,P36-Q36)) -> 0 | S36: =MAX(0,P36-Q36-R36) -> 1195423 | T36: =MAX(0,O36) -> 0 | U36: =IF(N36>=J36,"✓","") | V36: =IF(F36<=0,"✗","")
A37: 8 | B37: =(B36-Q36)*( 1+Rates!$B$3) -> 0 | C37: =(C36-R36)*(1+Rates!$B$4) -> 0 | D37: =(D36-S36+T36)*(1+Rates!$B$5) -> 16661715 | E37: =E36*(1+Rates!$B$6) -> 34214226 | F37: =B37+C37+D37+E37 -> 50875942 | G37: =G36*(1+Rates!$B$8) -> 1147570.6 | H37: =H36*(1+Rates!$B$9) -> 824729.37 | I37: 0 | J37: =G37+H37+I37 -> 1972300 | K37: =K36*(1+Rates!$B$10) -> 0 | L37: =E37*Rates!$B$7 -> 684284.53 | M37: =IF(A37>=$B$26,IF(M36=0,$B$12*12,M36*(1+Rates!$B$10)),0) -> 0 | N37: =K37+L37+M37 -> 684284.53 | O37: =N37-J37 -> -1288015.5 | P37: =MAX(0,-O37) -> 1288015.5 | Q37: =MIN(B37,P37) -> 0 | R37: =MIN(C37,MAX(0,P37-Q37)) -> 0 | S37: =MAX(0,P37-Q37-R37) -> 1288015.5 | T37: =MAX(0,O37) -> 0 | U37: =IF(N37>=J37,"✓","") | V37: =IF(F37<=0,"✗","")
A38: 9 | B38: =(B37-Q37)*( 1+Rates!$B$3) -> 0 | C38: =(C37-R37)*(1+Rates!$B$4) -> 0 | D38: =(D37-S37+T37)*(1+Rates!$B$5) -> 16911070 | E38: =E37*(1+Rates!$B$6) -> 35582795 | F38: =B38+C38+D38+E38 -> 52493865 | G38: =G37*(1+Rates!$B$8) -> 1216424.9 | H38: =H37*(1+Rates!$B$9) -> 882460.42 | I38: 0 | J38: =G38+H38+I38 -> 2098885.3 | K38: =K37*(1+Rates!$B$10) -> 0 | L38: =E38*Rates!$B$7 -> 711655.91 | M38: =IF(A38>=$B$26,IF(M37=0,$B$12*12,M37*(1+Rates!$B$10)),0) -> 0 | N38: =K38+L38+M38 -> 711655.91 | O38: =N38-J38 -> -1387229.4 | P38: =MAX(0,-O38) -> 1387229.4 | Q38: =MIN(B38,P38) -> 0 | R38: =MIN(C38,MAX(0,P38-Q38)) -> 0 | S38: =MAX(0,P38-Q38-R38) -> 1387229.4 | T38: =MAX(0,O38) -> 0 | U38: =IF(N38>=J38,"✓","") | V38: =IF(F38<=0,"✗","")
A39: 10 | B39: =(B38-Q38)*( 1+Rates!$B$3) -> 0 | C39: =(C38-R38)*(1+Rates!$B$4) -> 0 | D39: =(D38-S38+T38)*(1+Rates!$B$5) -> 17076225 | E39: =E38*(1+Rates!$B$6) -> 37006107 | F39: =B39+C39+D39+E39 -> 54082332 | G39: =G38*(1+Rates!$B$8) -> 1289410.3 | H39: =H38*(1+Rates!$B$9) -> 944232.65 | I39: 0 | J39: =G39+H39+I39 -> 2233643 | K39: =K38*(1+Rates!$B$10) -> 0 | L39: =E39*Rates!$B$7 -> 740122.14 | M39: =IF(A39>=$B$26,IF(M38=0,$B$12*12,M38*(1+Rates!$B$10)),0) -> 0 | N39: =K39+L39+M39 -> 740122.14 | O39: =N39-J39 -> -1493520.9 | P39: =MAX(0,-O39) -> 1493520.9 | Q39: =MIN(B39,P39) -> 0 | R39: =MIN(C39,MAX(0,P39-Q39)) -> 0 | S39: =MAX(0,P39-Q39-R39) -> 1493520.9 | T39: =MAX(0,O39) -> 0 | U39: =IF(N39>=J39,"✓","") | V39: =IF(F39<=0,"✗","")
A40: 11 | B40: =(B39-Q39)*( 1+Rates!$B$3) -> 0 | C40: =(C39-R39)*(1+Rates!$B$4) -> 0 | D40: =(D39-S39+T39)*(1+Rates!$B$5) -> 17140974 | E40: =E39*(1+Rates!$B$6) -> 38486351 | F40: =B40+C40+D40+E40 -> 55627326 | G40: =G39*(1+Rates!$B$8) -> 1366775 | H40: =H39*(1+Rates!$B$9) -> 1010328.9 | I40: 0 | J40: =G40+H40+I40 -> 2377103.9 | K40: =K39*(1+Rates!$B$10) -> 0 | L40: =E40*Rates!$B$7 -> 769727.03 | M40: =IF(A40>=$B$26,IF(M39=0,$B$12*12,M39*(1+Rates!$B$10)),0) -> 0 | N40: =K40+L40+M40 -> 769727.03 | O40: =N40-J40 -> -1607376.9 | P40: =MAX(0,-O40) -> 1607376.9 | Q40: =MIN(B40,P40) -> 0 | R40: =MIN(C40,MAX(0,P40-Q40)) -> 0 | S40: =MAX(0,P40-Q40-R40) -> 1607376.9 | T40: =MAX(0,O40) -> 0 | U40: =IF(N40>=J40,"✓","") | V40: =IF(F40<=0,"✗","")
A41: 12 | B41: =(B40-Q40)*( 1+Rates!$B$3) -> 0 | C41: =(C40-R40)*(1+Rates!$B$4) -> 0 | D41: =(D40-S40+T40)*(1+Rates!$B$5) -> 17086957 | E41: =E40*(1+Rates!$B$6) -> 40025805 | F41: =B41+C41+D41+E41 -> 57112762 | G41: =G40*(1+Rates!$B$8) -> 1448781.5 | H41: =H40*(1+Rates!$B$9) -> 1081052 | I41: 0 | J41: =G41+H41+I41 -> 2529833.4 | K41: =K40*(1+Rates!$B$10) -> 0 | L41: =E41*Rates!$B$7 -> 800516.11 | M41: =IF(A41>=$B$26,IF(M40=0,$B$12*12,M40*(1+Rates!$B$10)),0) -> 0 | N41: =K41+L41+M41 -> 800516.11 | O41: =N41-J41 -> -1729317.3 | P41: =MAX(0,-O41) -> 1729317.3 | Q41: =MIN(B41,P41) -> 0 | R41: =MIN(C41,MAX(0,P41-Q41)) -> 0 | S41: =MAX(0,P41-Q41-R41) -> 1729317.3 | T41: =MAX(0,O41) -> 0 | U41: =IF(N41>=J41,"✓","") | V41: =IF(F41<=0,"✗","")
... A49: 20 | B49: =(B48-Q48)*( 1+Rates!$B$3) -> 0 | C49: =(C48-R48)*(1+Rates!$B$4) -> 0 | D49: =(D48-S48+T48)*(1+Rates!$B$5) -> 9236856.7 | E49: =E48*(1+Rates!$B$6) -> 54778079 | F49: =B49+C49+D49+E49 -> 64014935 | G49: =G48*(1+Rates!$B$8) -> 2309137.5 | H49: =H48*(1+Rates!$B$9) -> 1857448.5 | I49: 0 | J49: =G49+H49+I49 -> 4166586.1 | K49: =K48*(1+Rates!$B$10) -> 0 | L49: =E49*Rates!$B$7 -> 1095561.6 | M49: =IF(A49>=$B$26,IF(M48=0,$B$12*12,M48*(1+Rates!$B$10)),0) -> 0 | N49: =K49+L49+M49 -> 1095561.6 | O49: =N49-J49 -> -3071024.5 | P49: =MAX(0,-O49) -> 3071024.5 | Q49: =MIN(B49,P49) -> 0 | R49: =MIN(C49,MAX(0,P49-Q49)) -> 0 | S49: =MAX(0,P49-Q49-R49) -> 3071024.5 | T49: =MAX(0,O49) -> 0 | U49: =IF(N49>=J49,"✓","") | V49: =IF(F49<=0,"✗","")
...

Sheet RETIRE_Std
A1: RETIREMENT — Standard Tier: 20-Year Projection
A2: Input | B2: Value | C2: Notes
A3: Monthly Expenses (total) | B3: 80000 | C3: ₹/month
A4: Liquid Savings | B4: 2000000 | C4: FD, savings, liquid MFs
A5: Semi-liquid Savings | B5: 500000 | C5: Debt MFs, bonds
A6: Growth Assets | B6: 1500000 | C6: Equity MFs, stocks
A7: Property Value | B7: 0 | C7: Residential / commercial
A8: Monthly Passive Income | B8: 0 | C8: Dividends, rent, royalties
A9: Emergency Fund Months | B9: 6 | C9: months of needs locked
A10: One-time Expenses | B10: 0 | C10: Large upfront costs
A11: Current Age | B11: 50 | C11: years
A12: Retirement Age | B12: 60 | C12: years
A13: Life Expectancy | B13: 85 | C13: years
A14: Pension Monthly | B14: 0 | C14: Pension/annuity once it begins
... A16: Gratuity Lumpsum | B16: 0 | C16: One-time injection at retirement
A18: Derived Inputs
A19: Monthly Survival (Needs) | B19: =B3*Rates!$B$13 -> 48000 | C19: monthly_expenses × needs%
A20: Emergency Lock | B20: =B19*B9 -> 288000
A21: Proj. Liquid (start) | B21: =MAX(0,B4-MIN(B4,B20+B10)) -> 1712000
A22: Proj. Semi (start) | B22: =MAX(0,B5-MIN(B5,MAX(0,B20+B10-B4))) -> 500000
A23: Total Assets | B23: =B4+B5+B6+B7 -> 4000000
A24: Required Corpus (25×) | B24: =B3*12*25 -> 24000000
A25: Years to Retirement | B25: =MAX(0,B12-B11) -> 10
A26: Pension Start Year (offset) | B26: =MAX(0,B15-B11) -> 10 | C26: pension_start_age − current_age
A27: Retirement Year (offset) | B27: =B25 -> 10
A29: Year | B29: Liquid (start) | C29: Semi (start) | D29: Growth (start) | E29: Property (start) | F29: Total Assets | G29: Annual Needs | H29: Annual Wants | I29: One-time | J29: Total Expenses | K29: Passive Income | L29: Rental Income | M29: Scenario Income | N29: Total Income | O29: Net Cashflow | P29: Deficit | Q29: Draw Liquid | R29: Draw Semi | S29: Draw Growth | T29: Surplus→Growth | U29: Free-up? | V29: Depleted?
A30: 0 | B30: =B21 -> 1712000 | C30: =B22 -> 500000 | D30: =$B$6 -> 1500000 | E30: =$B$7 -> 0 | F30: =B30+C30+D30+E30 -> 3712000 | G30: =B19*12 -> 576000 | H30: =B3*Rates!$B$14*12 -> 384000 | I30: 0 | J30: =G30+H30+I30 -> 960000 | K30: =$B$8*12 -> 0 | L30: =E30*Rates!$B$7 -> 0 | M30: =IF(A30>=$B$26,$B$14*12,0) -> 0 | N30: =K30+L30+M30 -> 0 | O30: =N30-J30 -> -960000 | P30: =MAX(0,-O30) -> 960000 | Q30: =MIN(B30,P30) -> 960000 | R30: =MIN(C30,MAX(0,P30-Q30)) -> 0 | S30: =MAX(0,P30-Q30-R30) -> 0 | T30: =MAX(0,O30) -> 0 | U30: =IF(N30>=J30,"✓","") | V30: =IF(F30<=0,"✗","")
A31: 1 | B31: =(B30-Q30)*(1+Rates!$B$3) -> 789600 | C31: =(C30-R30)*(1+Rates!$B$4) -> 540000 | D31: =(D30-S30+T30+IF(A31=$B$27,$B$16,0))*(1+Rates!$B$5) -> 1650000 | E31: =E30*(1+Rates!$B$6) -> 0 | F31: =B31+C31+D31+E31 -> 2979600 | G31: =G30*(1+Rates!$B$8) -> 610560 | H31: =H30*(1+Rates!$B$9) -> 410880 | I31: 0 | J31: =G31+H31+I31 -> 1021440 | K31: =K30*(1+Rates!$B$10) -> 0 | L31: =E31*Rates!$B$7 -> 0 | M31: =IF(A31>=$B$26,IF(M30=0,$B$14*12,M30*(1+Rates!$B$12)),0) -> 0 | N31: =K31+L31+M31 -> 0 | O31: =N31-J31 -> -1021440 | P31: =MAX(0,-O31) -> 1021440 | Q31: =MIN(B31,P31) -> 789600 | R31: =MIN(C31,MAX(0,P31-Q31)) -> 231840 | S31: =MAX(0,P31-Q31-R31) -> 0 | T31: =MAX(0,O31) -> 0 | U31: =IF(N31>=J31,"✓","") | V31: =IF(F31<=0,"✗","")
A32: 2 | B32: =(B31-Q31)*(1+Rates!$B$3) -> 0 | C32: =(C31-R31)*(1+Rates!$B$4) -> 332812.8 | D32: =(D31-S31+T31+IF(A32=$B$27,$B$16,0))*(1+Rates!$B$5) -> 1815000 | E32: =E31*(1+Rates!$B$6) -> 0 | F32: =B32+C32+D32+E32 -> 2147812.8 | G32: =G31*(1+Rates!$B$8) -> 647193.6 | H32: =H31*(1+Rates!$B$9) -> 439641.6 | I32: 0 | J32: =G32+H32+I32 -> 1086835.2 | K32: =K31*(1+Rates!$B$10) -> 0 | L32: =E32*Rates!$B$7 -> 0 | M32: =IF(A32>=$B$26,IF(M31=0,$B$14*12,M31*(1+Rates!$B$12)),0) -> 0 | N32: =K32+L32+M32 -> 0 | O32: =N32-J32 -> -1086835.2 | P32: =MAX(0,-O32) -> 1086835.2 | Q32: =MIN(B32,P32) -> 0 | R32: =MIN(C32,MAX(0,P32-Q32)) -> 332812.8 | S32: =MAX(0,P32-Q32-R32) -> 754022.4 | T32: =MAX(0,O32) -> 0 | U32: =IF(N32>=J32,"✓","") | V32: =IF(F32<=0,"✗","")
A33: 3 | B33: =(B32-Q32)*(1+Rates!$B$3) -> 0 | C33: =(C32-R32)*(1+Rates!$B$4) -> 0 | D33: =(D32-S32+T32+IF(A33=$B$27,$B$16,0))*(1+Rates!$B$5) -> 1167075.4 | E33: =E32*(1+Rates!$B$6) -> 0 | F33: =B33+C33+D33+E33 -> 1167075.4 | G33: =G32*(1+Rates!$B$8) -> 686025.22 | H33: =H32*(1+Rates!$B$9) -> 470416.51 | I33: 0 | J33: =G33+H33+I33 -> 1156441.7 | K33: =K32*(1+Rates!$B$10) -> 0 | L33: =E33*Rates!$B$7 -> 0 | M33: =IF(A33>=$B$26,IF(M32=0,$B$14*12,M32*(1+Rates!$B$12)),0) -> 0 | N33: =K33+L33+M33 -> 0 | O33: =N33-J33 -> -1156441.7 | P33: =MAX(0,-O33) -> 1156441.7 | Q33: =MIN(B33,P33) -> 0 | R33: =MIN(C33,MAX(0,P33-Q33)) -> 0 | S33: =MAX(0,P33-Q33-R33) -> 1156441.7 | T33: =MAX(0,O33) -> 0 | U33: =IF(N33>=J33,"✓","") | V33: =IF(F33<=0,"✗","")
A34: 4 | B34: =(B33-Q33)*(1+Rates!$B$3) -> 0 | C34: =(C33-R33)*(1+Rates!$B$4) -> 0 | D34: =(D33-S33+T33+IF(A34=$B$27,$B$16,0))*(1+Rates!$B$5) -> 11696.995 | E34: =E33*(1+Rates!$B$6) -> 0 | F34: =B34+C34+D34+E34 -> 11696.995 | G34: =G33*(1+Rates!$B$8) -> 727186.73 | H34: =H33*(1+Rates!$B$9) -> 503345.67 | I34: 0 | J34: =G34+H34+I34 -> 1230532.4 | K34: =K33*(1+Rates!$B$10) -> 0 | L34: =E34*Rates!$B$7 -> 0 | M34: =IF(A34>=$B$26,IF(M33=0,$B$14*12,M33*(1+Rates!$B$12)),0) -> 0 | N34: =K34+L34+M34 -> 0 | O34: =N34-J34 -> -1230532.4 | P34: =MAX(0,-O34) -> 1230532.4 | Q34: =MIN(B34,P34) -> 0 | R34: =MIN(C34,MAX(0,P34-Q34)) -> 0 | S34: =MAX(0,P34-Q34-R34) -> 1230532.4 | T34: =MAX(0,O34) -> 0 | U34: =IF(N34>=J34,"✓","") | V34: =IF(F34<=0,"✗","")
A35: 5 | B35: =(B34-Q34)*(1+Rates!$B$3) -> 0 | C35: =(C34-R34)*(1+Rates!$B$4) -> 0 | D35: =(D34-S34+T34+IF(A35=$B$27,$B$16,0))*(1+Rates!$B$5) -> -1340718.9 | E35: =E34*(1+Rates!$B$6) -> 0 | F35: =B35+C35+D35+E35 -> -1340718.9 | G35: =G34*(1+Rates!$B$8) -> 770817.93 | H35: =H34*(1+Rates!$B$9) -> 538579.86 | I35: 0 | J35: =G35+H35+I35 -> 1309397.8 | K35: =K34*(1+Rates!$B$10) -> 0 | L35: =E35*Rates!$B$7 -> 0 | M35: =IF(A35>=$B$26,IF(M34=0,$B$14*12,M34*(1+Rates!$B$12)),0) -> 0 | N35: =K35+L35+M35 -> 0 | O35: =N35-J35 -> -1309397.8 | P35: =MAX(0,-O35) -> 1309397.8 | Q35: =MIN(B35,P35) -> 0 | R35: =MIN(C35,MAX(0,P35-Q35)) -> 0 | S35: =MAX(0,P35-Q35-R35) -> 1309397.8 | T35: =MAX(0,O35) -> 0 | U35: =IF(N35>=J35,"✓","") | V35: =IF(F35<=0,"✗","") -> ✗
A36: 6 | B36: =(B35-Q35)*(1+Rates!$B$3) -> 0 | C36: =(C35-R35)*(1+Rates!$B$4) -> 0 | D36: =(D35-S35+T35+IF(A36=$B$27,$B$16,0))*(1+Rates!$B$5) -> -2915128.4 | E36: =E35*(1+Rates!$B$6) -> 0 | F36: =B36+C36+D36+E36 -> -2915128.4 | G36: =G35*(1+Rates!$B$8) -> 817067.01 | H36: =H35*(1+Rates!$B$9) -> 576280.46 | I36: 0 | J36: =G36+H36+I36 -> 1393347.5 | K36: =K35*(1+Rates!$B$10) -> 0 | L36: =E36*Rates!$B$7 -> 0 | M36: =IF(A36>=$B$26,IF(M35=0,$B$14*12,M35*(1+Rates!$B$12)),0) -> 0 | N36: =K36+L36+M36 -> 0 | O36: =N36-J36 -> -1393347.5 | P36: =MAX(0,-O36) -> 1393347.5 | Q36: =MIN(B36,P36) -> 0 | R36: =MIN(C36,MAX(0,P36-Q36)) -> 0 | S36: =MAX(0,P36-Q36-R36) -> 1393347.5 | T36: =MAX(0,O36) -> 0 | U36: =IF(N36>=J36,"✓","") | V36: =IF(F36<=0,"✗","") -> ✗
A37: 7 | B37: =(B36-Q36)*(1+Rates!$B$3) -> 0 | C37: =(C36-R36)*(1+Rates!$B$4) -> 0 | D37: =(D36-S36+T36+IF(A37=$B$27,$B$16,0))*(1+Rates!$B$5) -> -4739323.5 | E37: =E36*(1+Rates!$B$6) -> 0 | F37: =B37+C37+D37+E37 -> -4739323.5 | G37: =G36*(1+Rates!$B$8) -> 866091.03 | H37: =H36*(1+Rates!$B$9) -> 616620.09 | I37: 0 | J37: =G37+H37+I37 -> 1482711.1 | K37: =K36*(1+Rates!$B$10) -> 0 | L37: =E37*Rates!$B$7 -> 0 | M37: =IF(A37>=$B$26,IF(M36=0,$B$14*12,M36*(1+Rates!$B$12)),0) -> 0 | N37: =K37+L37+M37 -> 0 | O37: =N37-J37 -> -1482711.1 | P37: =MAX(0,-O37) -> 1482711.1 | Q37: =MIN(B37,P37) -> 0 | R37: =MIN(C37,MAX(0,P37-Q37)) -> 0 | S37: =MAX(0,P37-Q37-R37) -> 1482711.1 | T37: =MAX(0,O37) -> 0 | U37: =IF(N37>=J37,"✓","") | V37: =IF(F37<=0,"✗","") -> ✗
A38: 8 | B38: =(B37-Q37)*(1+Rates!$B$3) -> 0 | C38: =(C37-R37)*(1+Rates!$B$4) -> 0 | D38: =(D37-S37+T37+IF(A38=$B$27,$B$16,0))*(1+Rates!$B$5) -> -6844238 | E38: =E37*(1+Rates!$B$6) -> 0 | F38: =B38+C38+D38+E38 -> -6844238 | G38: =G37*(1+Rates!$B$8) -> 918056.49 | H38: =H37*(1+Rates!$B$9) -> 659783.49 | I38: 0 | J38: =G38+H38+I38 -> 1577840 | K38: =K37*(1+Rates!$B$10) -> 0 | L38: =E38*Rates!$B$7 -> 0 | M38: =IF(A38>=$B$26,IF(M37=0,$B$14*12,M37*(1+Rates!$B$12)),0) -> 0 | N38: =K38+L38+M38 -> 0 | O38: =N38-J38 -> -1577840 | P38: =MAX(0,-O38) -> 1577840 | Q38: =MIN(B38,P38) -> 0 | R38: =MIN(C38,MAX(0,P38-Q38)) -> 0 | S38: =MAX(0,P38-Q38-R38) -> 1577840 | T38: =MAX(0,O38) -> 0 | U38: =IF(N38>=J38,"✓","") | V38: =IF(F38<=0,"✗","") -> ✗
A39: 9 | B39: =(B38-Q38)*(1+Rates!$B$3) -> 0 | C39: =(C38-R38)*(1+Rates!$B$4) -> 0 | D39: =(D38-S38+T38+IF(A39=$B$27,$B$16,0))*(1+Rates!$B$5) -> -9264285.8 | E39: =E38*(1+Rates!$B$6) -> 0 | F39: =B39+C39+D39+E39 -> -9264285.8 | G39: =G38*(1+Rates!$B$8) -> 973139.88 | H39: =H38*(1+Rates!$B$9) -> 705968.34 | I39: 0 | J39: =G39+H39+I39 -> 1679108.2 | K39: =K38*(1+Rates!$B$10) -> 0 | L39: =E39*Rates!$B$7 -> 0 | M39: =IF(A39>=$B$26,IF(M38=0,$B$14*12,M38*(1+Rates!$B$12)),0) -> 0 | N39: =K39+L39+M39 -> 0 | O39: =N39-J39 -> -1679108.2 | P39: =MAX(0,-O39) -> 1679108.2 | Q39: =MIN(B39,P39) -> 0 | R39: =MIN(C39,MAX(0,P39-Q39)) -> 0 | S39: =MAX(0,P39-Q39-R39) -> 1679108.2 | T39: =MAX(0,O39) -> 0 | U39: =IF(N39>=J39,"✓","") | V39: =IF(F39<=0,"✗","") -> ✗
A40: 10 | B40: =(B39-Q39)*(1+Rates!$B$3) -> 0 | C40: =(C39-R39)*(1+Rates!$B$4) -> 0 | D40: =(D39-S39+T39+IF(A40=$B$27,$B$16,0))*(1+Rates!$B$5) -> -12037733 | E40: =E39*(1+Rates!$B$6) -> 0 | F40: =B40+C40+D40+E40 -> -12037733 | G40: =G39*(1+Rates!$B$8) -> 1031528.3 | H40: =H39*(1+Rates!$B$9) -> 755386.12 | I40: 0 | J40: =G40+H40+I40 -> 1786914.4 | K40: =K39*(1+Rates!$B$10) -> 0 | L40: =E40*Rates!$B$7 -> 0 | M40: =IF(A40>=$B$26,IF(M39=0,$B$14*12,M39*(1+Rates!$B$12)),0) -> 0 | N40: =K40+L40+M40 -> 0 | O40: =N40-J40 -> -1786914.4 | P40: =MAX(0,-O40) -> 1786914.4 | Q40: =MIN(B40,P40) -> 0 | R40: =MIN(C40,MAX(0,P40-Q40)) -> 0 | S40: =MAX(0,P40-Q40-R40) -> 1786914.4 | T40: =MAX(0,O40) -> 0 | U40: =IF(N40>=J40,"✓","") | V40: =IF(F40<=0,"✗","") -> ✗
A41: 11 | B41: =(B40-Q40)*(1+Rates!$B$3) -> 0 | C41: =(C40-R40)*(1+Rates!$B$4) -> 0 | D41: =(D40-S40+T40+IF(A41=$B$27,$B$16,0))*(1+Rates!$B$5) -> -15207113 | E41: =E40*(1+Rates!$B$6) -> 0 | F41: =B41+C41+D41+E41 -> -15207113 | G41: =G40*(1+Rates!$B$8) -> 1093420 | H41: =H40*(1+Rates!$B$9) -> 808263.15 | I41: 0 | J41: =G41+H41+I41 -> 1901683.1 | K41: =K40*(1+Rates!$B$10) -> 0 | L41: =E41*Rates!$B$7 -> 0 | M41: =IF(A41>=$B$26,IF(M40=0,$B$14*12,M40*(1+Rates!$B$12)),0) -> 0 | N41: =K41+L41+M41 -> 0 | O41: =N41-J41 -> -1901683.1 | P41: =MAX(0,-O41) -> 1901683.1 | Q41: =MIN(B41,P41) -> 0 | R41: =MIN(C41,MAX(0,P41-Q41)) -> 0 | S41: =MAX(0,P41-Q41-R41) -> 1901683.1 | T41: =MAX(0,O41) -> 0 | U41: =IF(N41>=J41,"✓","") | V41: =IF(F41<=0,"✗","") -> ✗
A42: 12 | B42: =(B41-Q41)*(1+Rates!$B$3) -> 0 | C42: =(C41-R41)*(1+Rates!$B$4) -> 0 | D42: =(D41-S41+T41+IF(A42=$B$27,$B$16,0))*(1+Rates!$B$5) -> -18819675 | E42: =E41*(1+Rates!$B$6) -> 0 | F42: =B42+C42+D42+E42 -> -18819675 | G42: =G41*(1+Rates!$B$8) -> 1159025.2 | H42: =H41*(1+Rates!$B$9) -> 864841.57 | I42: 0 | J42: =G42+H42+I42 -> 2023866.7 | K42: =K41*(1+Rates!$B$10) -> 0 | L42: =E42*Rates!$B$7 -> 0 | M42: =IF(A42>=$B$26,IF(M41=0,$B$14*12,M41*(1+Rates!$B$12)),0) -> 0 | N42: =K42+L42+M42 -> 0 | O42: =N42-J42 -> -2023866.7 | P42: =MAX(0,-O42) -> 2023866.7 | Q42: =MIN(B42,P42) -> 0 | R42: =MIN(C42,MAX(0,P42-Q42)) -> 0 | S42: =MAX(0,P42-Q42-R42) -> 2023866.7 | T42: =MAX(0,O42) -> 0 | U42: =IF(N42>=J42,"✓","") | V42: =IF(F42<=0,"✗","") -> ✗
... A50: 20 | B50: =(B49-Q49)*(1+Rates!$B$3) -> 0 | C50: =(C49-R49)*(1+Rates!$B$4) -> 0 | D50: =(D49-S49+T49+IF(A50=$B$27,$B$16,0))*(1+Rates!$B$5) -> -71353520 | E50: =E49*(1+Rates!$B$6) -> 0 | F50: =B50+C50+D50+E50 -> -71353520 | G50: =G49*(1+Rates!$B$8) -> 1847310 | H50: =H49*(1+Rates!$B$9) -> 1485958.8 | I50: 0 | J50: =G50+H50+I50 -> 3333268.9 | K50: =K49*(1+Rates!$B$10) -> 0 | L50: =E50*Rates!$B$7 -> 0 | M50: =IF(A50>=$B$26,IF(M49=0,$B$14*12,M49*(1+Rates!$B$12)),0) -> 0 | N50: =K50+L50+M50 -> 0 | O50: =N50-J50 -> -3333268.9 | P50: =MAX(0,-O50) -> 3333268.9 | Q50: =MIN(B50,P50) -> 0 | R50: =MIN(C50,MAX(0,P50-Q50)) -> 0 | S50: =MAX(0,P50-Q50-R50) -> 3333268.9 | T50: =MAX(0,O50) -> 0 | U50: =IF(N50>=J50,"✓","") | V50: =IF(F50<=0,"✗","") -> ✗
...
